Traceback (most recent call last):
  File "/opt/hostedtoolcache/Python/3.9.19/x64/lib/python3.9/site-packages/jupyter_cache/executors/utils.py", line 58, in single_nb_execution
    executenb(
  File "/opt/hostedtoolcache/Python/3.9.19/x64/lib/python3.9/site-packages/nbclient/client.py", line 1314, in execute
    return NotebookClient(nb=nb, resources=resources, km=km, **kwargs).execute()
  File "/opt/hostedtoolcache/Python/3.9.19/x64/lib/python3.9/site-packages/jupyter_core/utils/__init__.py", line 165, in wrapped
    return loop.run_until_complete(inner)
  File "/opt/hostedtoolcache/Python/3.9.19/x64/lib/python3.9/asyncio/base_events.py", line 647, in run_until_complete
    return future.result()
  File "/opt/hostedtoolcache/Python/3.9.19/x64/lib/python3.9/site-packages/nbclient/client.py", line 709, in async_execute
    await self.async_execute_cell(
  File "/opt/hostedtoolcache/Python/3.9.19/x64/lib/python3.9/site-packages/nbclient/client.py", line 1062, in async_execute_cell
    await self._check_raise_for_error(cell, cell_index, exec_reply)
  File "/opt/hostedtoolcache/Python/3.9.19/x64/lib/python3.9/site-packages/nbclient/client.py", line 918, in _check_raise_for_error
    raise CellExecutionError.from_cell_and_msg(cell, exec_reply_content)
nbclient.exceptions.CellExecutionError: An error occurred while executing the following cell:
------------------
def calcula_media(valores: list[int | float]) -> float:
    return sum(valores) / len(valores)
------------------


[0;31m---------------------------------------------------------------------------[0m
[0;31mTypeError[0m                                 Traceback (most recent call last)
Cell [0;32mIn[5], line 1[0m
[0;32m----> 1[0m [38;5;28;01mdef[39;00m [38;5;21mcalcula_media[39m(valores: [38;5;28mlist[39m[[38;5;28;43mint[39;49m[43m [49m[38;5;241;43m|[39;49m[43m [49m[38;5;28;43mfloat[39;49m]) [38;5;241m-[39m[38;5;241m>[39m [38;5;28mfloat[39m:
[1;32m      2[0m     [38;5;28;01mreturn[39;00m [38;5;28msum[39m(valores) [38;5;241m/[39m [38;5;28mlen[39m(valores)

[0;31mTypeError[0m: unsupported operand type(s) for |: 'type' and 'type'

